DEBUG:urllib3.connectionpool:Starting new HTTP connection (1): api.weatherapi.com:80
CRITICAL:root:HTTPConnectionPool(host='api.weatherapi.com', port=80): Max retries exceeded with url: /v1/forecast.json?key=e38e088af196452e88f145935230903&q=lahore&hour=4&days=3&aqi=yes (Caused by NewConnectionError('<urllib3.connection.HTTPConnection object at 0x00000233D14F7750>: Failed to establish a new connection: [Errno 11001] getaddrinfo failed'))
DEBUG:urllib3.connectionpool:Starting new HTTP connection (1): api.weatherapi.com:80
ERROR:root:Exception
Traceback (most recent call last):
  File "C:\Users\talhatahir\AppData\Local\Programs\Python\Python311\Lib\site-packages\urllib3\connection.py", line 174, in _new_conn
    conn = connection.create_connection(
           ^^^^^^^^^^^^^^^^^^^^^^^^^^^^^
  File "C:\Users\talhatahir\AppData\Local\Programs\Python\Python311\Lib\site-packages\urllib3\util\connection.py", line 72, in create_connection
    for res in socket.getaddrinfo(host, port, family, socket.SOCK_STREAM):
               ^^^^^^^^^^^^^^^^^^^^^^^^^^^^^^^^^^^^^^^^^^^^^^^^^^^^^^^^^^
  File "C:\Users\talhatahir\AppData\Local\Programs\Python\Python311\Lib\socket.py", line 962, in getaddrinfo
    for res in _socket.getaddrinfo(host, port, family, type, proto, flags):
               ^^^^^^^^^^^^^^^^^^^^^^^^^^^^^^^^^^^^^^^^^^^^^^^^^^^^^^^^^^^
socket.gaierror: [Errno 11001] getaddrinfo failed

During handling of the above exception, another exception occurred:

Traceback (most recent call last):
  File "C:\Users\talhatahir\AppData\Local\Programs\Python\Python311\Lib\site-packages\urllib3\connectionpool.py", line 703, in urlopen
    httplib_response = self._make_request(
                       ^^^^^^^^^^^^^^^^^^^
  File "C:\Users\talhatahir\AppData\Local\Programs\Python\Python311\Lib\site-packages\urllib3\connectionpool.py", line 398, in _make_request
    conn.request(method, url, **httplib_request_kw)
  File "C:\Users\talhatahir\AppData\Local\Programs\Python\Python311\Lib\site-packages\urllib3\connection.py", line 239, in request
    super(HTTPConnection, self).request(method, url, body=body, headers=headers)
  File "C:\Users\talhatahir\AppData\Local\Programs\Python\Python311\Lib\http\client.py", line 1282, in request
    self._send_request(method, url, body, headers, encode_chunked)
  File "C:\Users\talhatahir\AppData\Local\Programs\Python\Python311\Lib\http\client.py", line 1328, in _send_request
    self.endheaders(body, encode_chunked=encode_chunked)
  File "C:\Users\talhatahir\AppData\Local\Programs\Python\Python311\Lib\http\client.py", line 1277, in endheaders
    self._send_output(message_body, encode_chunked=encode_chunked)
  File "C:\Users\talhatahir\AppData\Local\Programs\Python\Python311\Lib\http\client.py", line 1037, in _send_output
    self.send(msg)
  File "C:\Users\talhatahir\AppData\Local\Programs\Python\Python311\Lib\http\client.py", line 975, in send
    self.connect()
  File "C:\Users\talhatahir\AppData\Local\Programs\Python\Python311\Lib\site-packages\urllib3\connection.py", line 205, in connect
    conn = self._new_conn()
           ^^^^^^^^^^^^^^^^
  File "C:\Users\talhatahir\AppData\Local\Programs\Python\Python311\Lib\site-packages\urllib3\connection.py", line 186, in _new_conn
    raise NewConnectionError(
urllib3.exceptions.NewConnectionError: <urllib3.connection.HTTPConnection object at 0x000002B5D0859790>: Failed to establish a new connection: [Errno 11001] getaddrinfo failed

During handling of the above exception, another exception occurred:

Traceback (most recent call last):
  File "C:\Users\talhatahir\AppData\Local\Programs\Python\Python311\Lib\site-packages\requests\adapters.py", line 489, in send
    resp = conn.urlopen(
           ^^^^^^^^^^^^^
  File "C:\Users\talhatahir\AppData\Local\Programs\Python\Python311\Lib\site-packages\urllib3\connectionpool.py", line 787, in urlopen
    retries = retries.increment(
              ^^^^^^^^^^^^^^^^^^
  File "C:\Users\talhatahir\AppData\Local\Programs\Python\Python311\Lib\site-packages\urllib3\util\retry.py", line 592, in increment
    raise MaxRetryError(_pool, url, error or ResponseError(cause))
urllib3.exceptions.MaxRetryError: HTTPConnectionPool(host='api.weatherapi.com', port=80): Max retries exceeded with url: /v1/forecast.json?key=e38e088af196452e88f145935230903&q=lahore&hour=4&days=3&aqi=yes (Caused by NewConnectionError('<urllib3.connection.HTTPConnection object at 0x000002B5D0859790>: Failed to establish a new connection: [Errno 11001] getaddrinfo failed'))

During handling of the above exception, another exception occurred:

Traceback (most recent call last):
  File "D:\PythonTrainee\question_6.py", line 21, in __fetch
    response = requests.get(url).json()
               ^^^^^^^^^^^^^^^^^
  File "C:\Users\talhatahir\AppData\Local\Programs\Python\Python311\Lib\site-packages\requests\api.py", line 73, in get
    return request("get", url, params=params, **kwargs)
           ^^^^^^^^^^^^^^^^^^^^^^^^^^^^^^^^^^^^^^^^^^^^
  File "C:\Users\talhatahir\AppData\Local\Programs\Python\Python311\Lib\site-packages\requests\api.py", line 59, in request
    return session.request(method=method, url=url, **kwargs)
           ^^^^^^^^^^^^^^^^^^^^^^^^^^^^^^^^^^^^^^^^^^^^^^^^^
  File "C:\Users\talhatahir\AppData\Local\Programs\Python\Python311\Lib\site-packages\requests\sessions.py", line 587, in request
    resp = self.send(prep, **send_kwargs)
           ^^^^^^^^^^^^^^^^^^^^^^^^^^^^^^
  File "C:\Users\talhatahir\AppData\Local\Programs\Python\Python311\Lib\site-packages\requests\sessions.py", line 701, in send
    r = adapter.send(request, **kwargs)
        ^^^^^^^^^^^^^^^^^^^^^^^^^^^^^^^
  File "C:\Users\talhatahir\AppData\Local\Programs\Python\Python311\Lib\site-packages\requests\adapters.py", line 565, in send
    raise ConnectionError(e, request=request)
requests.exceptions.ConnectionError: HTTPConnectionPool(host='api.weatherapi.com', port=80): Max retries exceeded with url: /v1/forecast.json?key=e38e088af196452e88f145935230903&q=lahore&hour=4&days=3&aqi=yes (Caused by NewConnectionError('<urllib3.connection.HTTPConnection object at 0x000002B5D0859790>: Failed to establish a new connection: [Errno 11001] getaddrinfo failed'))
DEBUG:urllib3.connectionpool:Starting new HTTP connection (1): api.weatherapi.com:80
DEBUG:urllib3.connectionpool:http://api.weatherapi.com:80 "GET /v1/forecast.json?key=e38e088af196452e88f145935230903&q=lahore&hour=4&days=3&aqi=yes HTTP/1.1" 200 None
DEBUG:urllib3.connectionpool:Starting new HTTP connection (1): api.weatherapi.com:80
DEBUG:urllib3.connectionpool:http://api.weatherapi.com:80 "GET /v1/forecast.json?key=e38e088af196452e88f145935230903&q=lahore&hour=4&days=3&aqi=yes HTTP/1.1" 200 None
DEBUG:urllib3.connectionpool:Starting new HTTP connection (1): api.weatherapi.com:80
DEBUG:urllib3.connectionpool:http://api.weatherapi.com:80 "GET /v1/forecast.json?key=e38e088af196452e88f145935230903&q=lahore&hour=4&days=3&aqi=yes HTTP/1.1" 200 None
DEBUG:urllib3.connectionpool:Starting new HTTP connection (1): api.weatherapi.com:80
DEBUG:urllib3.connectionpool:http://api.weatherapi.com:80 "GET /v1/forecast.json?key=e38e088af196452e88f145935230903&q=lahore&hour=4&days=3&aqi=yes HTTP/1.1" 200 None
DEBUG:urllib3.connectionpool:Starting new HTTP connection (1): api.weatherapi.com:80
DEBUG:urllib3.connectionpool:http://api.weatherapi.com:80 "GET /v1/forecast.json?key=e38e088af196452e88f145935230903&q=lahore&hour=4&days=3&aqi=yes HTTP/1.1" 200 None
DEBUG:urllib3.connectionpool:Starting new HTTP connection (1): api.weatherapi.com:80
DEBUG:urllib3.connectionpool:http://api.weatherapi.com:80 "GET /v1/forecast.json?key=e38e088af196452e88f145935230903&q=lahore&hour=4&days=3&aqi=yes HTTP/1.1" 200 None
DEBUG:urllib3.connectionpool:Starting new HTTP connection (1): api.weatherapi.com:80
DEBUG:urllib3.connectionpool:http://api.weatherapi.com:80 "GET /v1/forecast.json?key=e38e088af196452e88f145935230903&q=lahore&hour=4&days=3&aqi=yes HTTP/1.1" 200 None
DEBUG:urllib3.connectionpool:Starting new HTTP connection (1): api.weatherapi.com:80
DEBUG:urllib3.connectionpool:http://api.weatherapi.com:80 "GET /v1/forecast.json?key=e38e088af196452e88f145935230903&q=lahore&hour=4&days=3&aqi=yes HTTP/1.1" 200 None
DEBUG:urllib3.connectionpool:Starting new HTTP connection (1): api.weatherapi.com:80
DEBUG:urllib3.connectionpool:http://api.weatherapi.com:80 "GET /v1/forecast.json?key=e38e088af196452e88f145935230903&q=lahore&hour=4&days=3&aqi=yes HTTP/1.1" 200 None
